[2022-10-26 13:34:13,088] {taskinstance.py:1159} INFO - Dependencies all met for <TaskInstance: load_raw_data.equipos_raw_create scheduled__2022-09-01T00:00:00+00:00 [queued]>
[2022-10-26 13:34:13,102] {taskinstance.py:1159} INFO - Dependencies all met for <TaskInstance: load_raw_data.equipos_raw_create scheduled__2022-09-01T00:00:00+00:00 [queued]>
[2022-10-26 13:34:13,102] {taskinstance.py:1356} INFO - 
--------------------------------------------------------------------------------
[2022-10-26 13:34:13,102] {taskinstance.py:1357} INFO - Starting attempt 2 of 2
[2022-10-26 13:34:13,102] {taskinstance.py:1358} INFO - 
--------------------------------------------------------------------------------
[2022-10-26 13:34:13,126] {taskinstance.py:1377} INFO - Executing <Task(PostgresOperator): equipos_raw_create> on 2022-09-01 00:00:00+00:00
[2022-10-26 13:34:13,133] {standard_task_runner.py:52} INFO - Started process 373 to run task
[2022-10-26 13:34:13,141] {standard_task_runner.py:79} INFO - Running: ['***', 'tasks', 'run', 'load_raw_data', 'equipos_raw_create', 'scheduled__2022-09-01T00:00:00+00:00', '--job-id', '9', '--raw', '--subdir', 'DAGS_FOLDER/raw-dag.py', '--cfg-path', '/tmp/tmpi0atdibs', '--error-file', '/tmp/tmpi6_77fe4']
[2022-10-26 13:34:13,143] {standard_task_runner.py:80} INFO - Job 9: Subtask equipos_raw_create
[2022-10-26 13:34:13,322] {task_command.py:369} INFO - Running <TaskInstance: load_raw_data.equipos_raw_create scheduled__2022-09-01T00:00:00+00:00 [running]> on host b1681a16582a
[2022-10-26 13:34:13,598] {taskinstance.py:1571} INFO - Exporting the following env vars:
AIRFLOW_CTX_DAG_OWNER=***
AIRFLOW_CTX_DAG_ID=load_raw_data
AIRFLOW_CTX_TASK_ID=equipos_raw_create
AIRFLOW_CTX_EXECUTION_DATE=2022-09-01T00:00:00+00:00
AIRFLOW_CTX_TRY_NUMBER=2
AIRFLOW_CTX_DAG_RUN_ID=scheduled__2022-09-01T00:00:00+00:00
[2022-10-26 13:34:13,713] {taskinstance.py:1889} ERROR - Task failed with exception
Traceback (most recent call last):
  File "/home/airflow/.local/lib/python3.7/site-packages/airflow/providers/postgres/operators/postgres.py", line 92, in execute
    self.hook.run(self.sql, self.autocommit, parameters=self.parameters)
  File "/home/airflow/.local/lib/python3.7/site-packages/airflow/hooks/dbapi.py", line 181, in run
    with closing(self.get_conn()) as conn:
  File "/home/airflow/.local/lib/python3.7/site-packages/airflow/providers/postgres/hooks/postgres.py", line 86, in get_conn
    conn = deepcopy(self.connection or self.get_connection(conn_id))
  File "/home/airflow/.local/lib/python3.7/site-packages/airflow/hooks/base.py", line 67, in get_connection
    conn = Connection.get_connection_from_secrets(conn_id)
  File "/home/airflow/.local/lib/python3.7/site-packages/airflow/models/connection.py", line 430, in get_connection_from_secrets
    raise AirflowNotFoundException(f"The conn_id `{conn_id}` isn't defined")
airflow.exceptions.AirflowNotFoundException: The conn_id `postgres-default` isn't defined
[2022-10-26 13:34:13,736] {taskinstance.py:1400} INFO - Marking task as FAILED. dag_id=load_raw_data, task_id=equipos_raw_create, execution_date=20220901T000000, start_date=20221026T133413, end_date=20221026T133413
[2022-10-26 13:34:13,779] {standard_task_runner.py:97} ERROR - Failed to execute job 9 for task equipos_raw_create (The conn_id `postgres-default` isn't defined; 373)
[2022-10-26 13:34:13,791] {local_task_job.py:156} INFO - Task exited with return code 1
[2022-10-26 13:34:13,962] {local_task_job.py:273} INFO - 0 downstream tasks scheduled from follow-on schedule check
