[2022-10-26 15:14:17,200] {taskinstance.py:1159} INFO - Dependencies all met for <TaskInstance: dbt_dim.deportistas_dim scheduled__2022-09-01T00:00:00+00:00 [queued]>
[2022-10-26 15:14:17,244] {taskinstance.py:1159} INFO - Dependencies all met for <TaskInstance: dbt_dim.deportistas_dim scheduled__2022-09-01T00:00:00+00:00 [queued]>
[2022-10-26 15:14:17,244] {taskinstance.py:1356} INFO - 
--------------------------------------------------------------------------------
[2022-10-26 15:14:17,245] {taskinstance.py:1357} INFO - Starting attempt 4 of 4
[2022-10-26 15:14:17,245] {taskinstance.py:1358} INFO - 
--------------------------------------------------------------------------------
[2022-10-26 15:14:17,267] {taskinstance.py:1377} INFO - Executing <Task(BashOperator): deportistas_dim> on 2022-09-01 00:00:00+00:00
[2022-10-26 15:14:17,272] {standard_task_runner.py:52} INFO - Started process 867 to run task
[2022-10-26 15:14:17,277] {standard_task_runner.py:79} INFO - Running: ['***', 'tasks', 'run', 'dbt_dim', 'deportistas_dim', 'scheduled__2022-09-01T00:00:00+00:00', '--job-id', '24', '--raw', '--subdir', 'DAGS_FOLDER/dbt_dim.py', '--cfg-path', '/tmp/tmpetq0hcus', '--error-file', '/tmp/tmp4u5t574q']
[2022-10-26 15:14:17,279] {standard_task_runner.py:80} INFO - Job 24: Subtask deportistas_dim
[2022-10-26 15:14:17,374] {task_command.py:369} INFO - Running <TaskInstance: dbt_dim.deportistas_dim scheduled__2022-09-01T00:00:00+00:00 [running]> on host 4af2e895db31
[2022-10-26 15:14:17,496] {taskinstance.py:1571} INFO - Exporting the following env vars:
AIRFLOW_CTX_DAG_OWNER=***
AIRFLOW_CTX_DAG_ID=dbt_dim
AIRFLOW_CTX_TASK_ID=deportistas_dim
AIRFLOW_CTX_EXECUTION_DATE=2022-09-01T00:00:00+00:00
AIRFLOW_CTX_TRY_NUMBER=4
AIRFLOW_CTX_DAG_RUN_ID=scheduled__2022-09-01T00:00:00+00:00
[2022-10-26 15:14:17,497] {subprocess.py:62} INFO - Tmp dir root location: 
 /tmp
[2022-10-26 15:14:17,498] {subprocess.py:74} INFO - Running command: ['bash', '-c', 'cd /opt/dbt/oly_dbt/models/dim_tables && dbt run --select +deportistas_dim']
[2022-10-26 15:14:17,510] {subprocess.py:85} INFO - Output:
[2022-10-26 15:14:21,457] {subprocess.py:92} INFO - [0m15:14:21  Encountered an error while reading the project:
[2022-10-26 15:14:21,458] {subprocess.py:92} INFO - [0m15:14:21    ERROR: Runtime Error
[2022-10-26 15:14:21,458] {subprocess.py:92} INFO -   Could not find profile named 'oly_dbt'
[2022-10-26 15:14:21,469] {subprocess.py:92} INFO - [0m15:14:21  Encountered an error:
[2022-10-26 15:14:21,470] {subprocess.py:92} INFO - Runtime Error
[2022-10-26 15:14:21,470] {subprocess.py:92} INFO -   Could not run dbt
[2022-10-26 15:14:21,786] {subprocess.py:96} INFO - Command exited with return code 2
[2022-10-26 15:14:21,822] {taskinstance.py:1889} ERROR - Task failed with exception
Traceback (most recent call last):
  File "/home/airflow/.local/lib/python3.7/site-packages/airflow/operators/bash.py", line 195, in execute
    f'Bash command failed. The command returned a non-zero exit code {result.exit_code}.'
airflow.exceptions.AirflowException: Bash command failed. The command returned a non-zero exit code 2.
[2022-10-26 15:14:21,829] {taskinstance.py:1400} INFO - Marking task as FAILED. dag_id=dbt_dim, task_id=deportistas_dim, execution_date=20220901T000000, start_date=20221026T151417, end_date=20221026T151421
[2022-10-26 15:14:21,864] {standard_task_runner.py:97} ERROR - Failed to execute job 24 for task deportistas_dim (Bash command failed. The command returned a non-zero exit code 2.; 867)
[2022-10-26 15:14:21,886] {local_task_job.py:156} INFO - Task exited with return code 1
[2022-10-26 15:14:21,968] {local_task_job.py:273} INFO - 0 downstream tasks scheduled from follow-on schedule check
