[2022-10-26 13:50:56,091] {taskinstance.py:1159} INFO - Dependencies all met for <TaskInstance: dbt_dim.eventos_dim scheduled__2022-09-01T00:00:00+00:00 [queued]>
[2022-10-26 13:50:56,108] {taskinstance.py:1159} INFO - Dependencies all met for <TaskInstance: dbt_dim.eventos_dim scheduled__2022-09-01T00:00:00+00:00 [queued]>
[2022-10-26 13:50:56,108] {taskinstance.py:1356} INFO - 
--------------------------------------------------------------------------------
[2022-10-26 13:50:56,109] {taskinstance.py:1357} INFO - Starting attempt 2 of 2
[2022-10-26 13:50:56,109] {taskinstance.py:1358} INFO - 
--------------------------------------------------------------------------------
[2022-10-26 13:50:56,133] {taskinstance.py:1377} INFO - Executing <Task(BashOperator): eventos_dim> on 2022-09-01 00:00:00+00:00
[2022-10-26 13:50:56,139] {standard_task_runner.py:52} INFO - Started process 789 to run task
[2022-10-26 13:50:56,143] {standard_task_runner.py:79} INFO - Running: ['***', 'tasks', 'run', 'dbt_dim', 'eventos_dim', 'scheduled__2022-09-01T00:00:00+00:00', '--job-id', '33', '--raw', '--subdir', 'DAGS_FOLDER/dbt_dim.py', '--cfg-path', '/tmp/tmpkyut0ax4', '--error-file', '/tmp/tmp8hn8mcrx']
[2022-10-26 13:50:56,144] {standard_task_runner.py:80} INFO - Job 33: Subtask eventos_dim
[2022-10-26 13:50:56,264] {task_command.py:369} INFO - Running <TaskInstance: dbt_dim.eventos_dim scheduled__2022-09-01T00:00:00+00:00 [running]> on host b1681a16582a
[2022-10-26 13:50:56,505] {taskinstance.py:1571} INFO - Exporting the following env vars:
AIRFLOW_CTX_DAG_OWNER=***
AIRFLOW_CTX_DAG_ID=dbt_dim
AIRFLOW_CTX_TASK_ID=eventos_dim
AIRFLOW_CTX_EXECUTION_DATE=2022-09-01T00:00:00+00:00
AIRFLOW_CTX_TRY_NUMBER=2
AIRFLOW_CTX_DAG_RUN_ID=scheduled__2022-09-01T00:00:00+00:00
[2022-10-26 13:50:56,507] {subprocess.py:62} INFO - Tmp dir root location: 
 /tmp
[2022-10-26 13:50:56,508] {subprocess.py:74} INFO - Running command: ['bash', '-c', 'cd /opt/dbt/oly_dbt && dbt run --select +eventos_dim']
[2022-10-26 13:50:56,528] {subprocess.py:85} INFO - Output:
[2022-10-26 13:50:56,531] {subprocess.py:92} INFO - bash: line 1: dbt: command not found
[2022-10-26 13:50:56,532] {subprocess.py:96} INFO - Command exited with return code 127
[2022-10-26 13:50:56,578] {taskinstance.py:1889} ERROR - Task failed with exception
Traceback (most recent call last):
  File "/home/airflow/.local/lib/python3.7/site-packages/airflow/operators/bash.py", line 195, in execute
    f'Bash command failed. The command returned a non-zero exit code {result.exit_code}.'
airflow.exceptions.AirflowException: Bash command failed. The command returned a non-zero exit code 127.
[2022-10-26 13:50:56,591] {taskinstance.py:1400} INFO - Marking task as FAILED. dag_id=dbt_dim, task_id=eventos_dim, execution_date=20220901T000000, start_date=20221026T135056, end_date=20221026T135056
[2022-10-26 13:50:56,639] {standard_task_runner.py:97} ERROR - Failed to execute job 33 for task eventos_dim (Bash command failed. The command returned a non-zero exit code 127.; 789)
[2022-10-26 13:50:56,677] {local_task_job.py:156} INFO - Task exited with return code 1
[2022-10-26 13:50:56,816] {local_task_job.py:273} INFO - 0 downstream tasks scheduled from follow-on schedule check
[2022-10-26 14:49:21,663] {taskinstance.py:1159} INFO - Dependencies all met for <TaskInstance: dbt_dim.eventos_dim scheduled__2022-09-01T00:00:00+00:00 [queued]>
[2022-10-26 14:49:21,687] {taskinstance.py:1159} INFO - Dependencies all met for <TaskInstance: dbt_dim.eventos_dim scheduled__2022-09-01T00:00:00+00:00 [queued]>
[2022-10-26 14:49:21,687] {taskinstance.py:1356} INFO - 
--------------------------------------------------------------------------------
[2022-10-26 14:49:21,687] {taskinstance.py:1357} INFO - Starting attempt 2 of 2
[2022-10-26 14:49:21,688] {taskinstance.py:1358} INFO - 
--------------------------------------------------------------------------------
[2022-10-26 14:49:21,730] {taskinstance.py:1377} INFO - Executing <Task(BashOperator): eventos_dim> on 2022-09-01 00:00:00+00:00
[2022-10-26 14:49:21,736] {standard_task_runner.py:52} INFO - Started process 355 to run task
[2022-10-26 14:49:21,741] {standard_task_runner.py:79} INFO - Running: ['***', 'tasks', 'run', 'dbt_dim', 'eventos_dim', 'scheduled__2022-09-01T00:00:00+00:00', '--job-id', '19', '--raw', '--subdir', 'DAGS_FOLDER/dbt_dim.py', '--cfg-path', '/tmp/tmpv_3tjxnk', '--error-file', '/tmp/tmpjhkyr7tt']
[2022-10-26 14:49:21,743] {standard_task_runner.py:80} INFO - Job 19: Subtask eventos_dim
[2022-10-26 14:49:21,852] {task_command.py:369} INFO - Running <TaskInstance: dbt_dim.eventos_dim scheduled__2022-09-01T00:00:00+00:00 [running]> on host 4af2e895db31
[2022-10-26 14:49:22,027] {taskinstance.py:1571} INFO - Exporting the following env vars:
AIRFLOW_CTX_DAG_OWNER=***
AIRFLOW_CTX_DAG_ID=dbt_dim
AIRFLOW_CTX_TASK_ID=eventos_dim
AIRFLOW_CTX_EXECUTION_DATE=2022-09-01T00:00:00+00:00
AIRFLOW_CTX_TRY_NUMBER=2
AIRFLOW_CTX_DAG_RUN_ID=scheduled__2022-09-01T00:00:00+00:00
[2022-10-26 14:49:22,029] {subprocess.py:62} INFO - Tmp dir root location: 
 /tmp
[2022-10-26 14:49:22,030] {subprocess.py:74} INFO - Running command: ['bash', '-c', 'cd /opt/dbt/oly_dbt/models/dim_tables && dbt run --select +eventos_dim']
[2022-10-26 14:49:22,047] {subprocess.py:85} INFO - Output:
[2022-10-26 14:49:25,167] {subprocess.py:92} INFO - [0m14:49:25  Encountered an error while reading the project:
[2022-10-26 14:49:25,168] {subprocess.py:92} INFO - [0m14:49:25    ERROR: Runtime Error
[2022-10-26 14:49:25,169] {subprocess.py:92} INFO -   Could not find profile named 'oly_dbt'
[2022-10-26 14:49:25,188] {subprocess.py:92} INFO - [0m14:49:25  Encountered an error:
[2022-10-26 14:49:25,188] {subprocess.py:92} INFO - Runtime Error
[2022-10-26 14:49:25,188] {subprocess.py:92} INFO -   Could not run dbt
[2022-10-26 14:49:25,448] {subprocess.py:96} INFO - Command exited with return code 2
[2022-10-26 14:49:25,487] {taskinstance.py:1889} ERROR - Task failed with exception
Traceback (most recent call last):
  File "/home/airflow/.local/lib/python3.7/site-packages/airflow/operators/bash.py", line 195, in execute
    f'Bash command failed. The command returned a non-zero exit code {result.exit_code}.'
airflow.exceptions.AirflowException: Bash command failed. The command returned a non-zero exit code 2.
[2022-10-26 14:49:25,496] {taskinstance.py:1400} INFO - Marking task as FAILED. dag_id=dbt_dim, task_id=eventos_dim, execution_date=20220901T000000, start_date=20221026T144921, end_date=20221026T144925
[2022-10-26 14:49:25,525] {standard_task_runner.py:97} ERROR - Failed to execute job 19 for task eventos_dim (Bash command failed. The command returned a non-zero exit code 2.; 355)
[2022-10-26 14:49:25,539] {local_task_job.py:156} INFO - Task exited with return code 1
[2022-10-26 14:49:25,603] {local_task_job.py:273} INFO - 0 downstream tasks scheduled from follow-on schedule check
