[2022-10-26 15:13:10,853] {taskinstance.py:1159} INFO - Dependencies all met for <TaskInstance: dbt_dim.eventos_dim scheduled__2022-09-01T00:00:00+00:00 [queued]>
[2022-10-26 15:13:10,876] {taskinstance.py:1159} INFO - Dependencies all met for <TaskInstance: dbt_dim.eventos_dim scheduled__2022-09-01T00:00:00+00:00 [queued]>
[2022-10-26 15:13:10,876] {taskinstance.py:1356} INFO - 
--------------------------------------------------------------------------------
[2022-10-26 15:13:10,876] {taskinstance.py:1357} INFO - Starting attempt 3 of 4
[2022-10-26 15:13:10,877] {taskinstance.py:1358} INFO - 
--------------------------------------------------------------------------------
[2022-10-26 15:13:10,902] {taskinstance.py:1377} INFO - Executing <Task(BashOperator): eventos_dim> on 2022-09-01 00:00:00+00:00
[2022-10-26 15:13:10,907] {standard_task_runner.py:52} INFO - Started process 838 to run task
[2022-10-26 15:13:10,913] {standard_task_runner.py:79} INFO - Running: ['***', 'tasks', 'run', 'dbt_dim', 'eventos_dim', 'scheduled__2022-09-01T00:00:00+00:00', '--job-id', '22', '--raw', '--subdir', 'DAGS_FOLDER/dbt_dim.py', '--cfg-path', '/tmp/tmpn0tth5zs', '--error-file', '/tmp/tmp9igs_3ej']
[2022-10-26 15:13:10,917] {standard_task_runner.py:80} INFO - Job 22: Subtask eventos_dim
[2022-10-26 15:13:11,057] {task_command.py:369} INFO - Running <TaskInstance: dbt_dim.eventos_dim scheduled__2022-09-01T00:00:00+00:00 [running]> on host 4af2e895db31
[2022-10-26 15:13:11,214] {taskinstance.py:1571} INFO - Exporting the following env vars:
AIRFLOW_CTX_DAG_OWNER=***
AIRFLOW_CTX_DAG_ID=dbt_dim
AIRFLOW_CTX_TASK_ID=eventos_dim
AIRFLOW_CTX_EXECUTION_DATE=2022-09-01T00:00:00+00:00
AIRFLOW_CTX_TRY_NUMBER=3
AIRFLOW_CTX_DAG_RUN_ID=scheduled__2022-09-01T00:00:00+00:00
[2022-10-26 15:13:11,216] {subprocess.py:62} INFO - Tmp dir root location: 
 /tmp
[2022-10-26 15:13:11,217] {subprocess.py:74} INFO - Running command: ['bash', '-c', 'cd /opt/dbt/oly_dbt/models/dim_tables && dbt run --select +eventos_dim']
[2022-10-26 15:13:11,227] {subprocess.py:85} INFO - Output:
[2022-10-26 15:13:15,942] {subprocess.py:92} INFO - [0m15:13:15  Encountered an error while reading the project:
[2022-10-26 15:13:15,944] {subprocess.py:92} INFO - [0m15:13:15    ERROR: Runtime Error
[2022-10-26 15:13:15,944] {subprocess.py:92} INFO -   Could not find profile named 'oly_dbt'
[2022-10-26 15:13:16,037] {subprocess.py:92} INFO - [0m15:13:16  Encountered an error:
[2022-10-26 15:13:16,037] {subprocess.py:92} INFO - Runtime Error
[2022-10-26 15:13:16,038] {subprocess.py:92} INFO -   Could not run dbt
[2022-10-26 15:13:16,303] {subprocess.py:96} INFO - Command exited with return code 2
[2022-10-26 15:13:16,365] {taskinstance.py:1889} ERROR - Task failed with exception
Traceback (most recent call last):
  File "/home/airflow/.local/lib/python3.7/site-packages/airflow/operators/bash.py", line 195, in execute
    f'Bash command failed. The command returned a non-zero exit code {result.exit_code}.'
airflow.exceptions.AirflowException: Bash command failed. The command returned a non-zero exit code 2.
[2022-10-26 15:13:16,371] {taskinstance.py:1400} INFO - Marking task as UP_FOR_RETRY. dag_id=dbt_dim, task_id=eventos_dim, execution_date=20220901T000000, start_date=20221026T151310, end_date=20221026T151316
[2022-10-26 15:13:16,396] {standard_task_runner.py:97} ERROR - Failed to execute job 22 for task eventos_dim (Bash command failed. The command returned a non-zero exit code 2.; 838)
[2022-10-26 15:13:16,426] {local_task_job.py:156} INFO - Task exited with return code 1
[2022-10-26 15:13:16,462] {local_task_job.py:273} INFO - 0 downstream tasks scheduled from follow-on schedule check
