[2022-10-26 13:49:54,959] {taskinstance.py:1159} INFO - Dependencies all met for <TaskInstance: dbt_dim.eventos_dim scheduled__2022-09-01T00:00:00+00:00 [queued]>
[2022-10-26 13:49:54,979] {taskinstance.py:1159} INFO - Dependencies all met for <TaskInstance: dbt_dim.eventos_dim scheduled__2022-09-01T00:00:00+00:00 [queued]>
[2022-10-26 13:49:54,979] {taskinstance.py:1356} INFO - 
--------------------------------------------------------------------------------
[2022-10-26 13:49:54,979] {taskinstance.py:1357} INFO - Starting attempt 1 of 2
[2022-10-26 13:49:54,979] {taskinstance.py:1358} INFO - 
--------------------------------------------------------------------------------
[2022-10-26 13:49:55,002] {taskinstance.py:1377} INFO - Executing <Task(BashOperator): eventos_dim> on 2022-09-01 00:00:00+00:00
[2022-10-26 13:49:55,008] {standard_task_runner.py:52} INFO - Started process 764 to run task
[2022-10-26 13:49:55,015] {standard_task_runner.py:79} INFO - Running: ['***', 'tasks', 'run', 'dbt_dim', 'eventos_dim', 'scheduled__2022-09-01T00:00:00+00:00', '--job-id', '32', '--raw', '--subdir', 'DAGS_FOLDER/dbt_dim.py', '--cfg-path', '/tmp/tmpur5idqbd', '--error-file', '/tmp/tmpjj3zj5te']
[2022-10-26 13:49:55,016] {standard_task_runner.py:80} INFO - Job 32: Subtask eventos_dim
[2022-10-26 13:49:55,186] {task_command.py:369} INFO - Running <TaskInstance: dbt_dim.eventos_dim scheduled__2022-09-01T00:00:00+00:00 [running]> on host b1681a16582a
[2022-10-26 13:49:55,438] {taskinstance.py:1571} INFO - Exporting the following env vars:
AIRFLOW_CTX_DAG_OWNER=***
AIRFLOW_CTX_DAG_ID=dbt_dim
AIRFLOW_CTX_TASK_ID=eventos_dim
AIRFLOW_CTX_EXECUTION_DATE=2022-09-01T00:00:00+00:00
AIRFLOW_CTX_TRY_NUMBER=1
AIRFLOW_CTX_DAG_RUN_ID=scheduled__2022-09-01T00:00:00+00:00
[2022-10-26 13:49:55,440] {subprocess.py:62} INFO - Tmp dir root location: 
 /tmp
[2022-10-26 13:49:55,441] {subprocess.py:74} INFO - Running command: ['bash', '-c', 'cd /opt/dbt/oly_dbt && dbt run --select +eventos_dim']
[2022-10-26 13:49:55,462] {subprocess.py:85} INFO - Output:
[2022-10-26 13:49:55,465] {subprocess.py:92} INFO - bash: line 1: dbt: command not found
[2022-10-26 13:49:55,466] {subprocess.py:96} INFO - Command exited with return code 127
[2022-10-26 13:49:55,500] {taskinstance.py:1889} ERROR - Task failed with exception
Traceback (most recent call last):
  File "/home/airflow/.local/lib/python3.7/site-packages/airflow/operators/bash.py", line 195, in execute
    f'Bash command failed. The command returned a non-zero exit code {result.exit_code}.'
airflow.exceptions.AirflowException: Bash command failed. The command returned a non-zero exit code 127.
[2022-10-26 13:49:55,507] {taskinstance.py:1400} INFO - Marking task as UP_FOR_RETRY. dag_id=dbt_dim, task_id=eventos_dim, execution_date=20220901T000000, start_date=20221026T134954, end_date=20221026T134955
[2022-10-26 13:49:55,547] {standard_task_runner.py:97} ERROR - Failed to execute job 32 for task eventos_dim (Bash command failed. The command returned a non-zero exit code 127.; 764)
[2022-10-26 13:49:55,600] {local_task_job.py:156} INFO - Task exited with return code 1
[2022-10-26 13:49:55,817] {local_task_job.py:273} INFO - 0 downstream tasks scheduled from follow-on schedule check
[2022-10-26 14:28:01,175] {taskinstance.py:1159} INFO - Dependencies all met for <TaskInstance: dbt_dim.eventos_dim scheduled__2022-09-01T00:00:00+00:00 [queued]>
[2022-10-26 14:28:01,205] {taskinstance.py:1159} INFO - Dependencies all met for <TaskInstance: dbt_dim.eventos_dim scheduled__2022-09-01T00:00:00+00:00 [queued]>
[2022-10-26 14:28:01,205] {taskinstance.py:1356} INFO - 
--------------------------------------------------------------------------------
[2022-10-26 14:28:01,206] {taskinstance.py:1357} INFO - Starting attempt 1 of 2
[2022-10-26 14:28:01,206] {taskinstance.py:1358} INFO - 
--------------------------------------------------------------------------------
[2022-10-26 14:28:01,233] {taskinstance.py:1377} INFO - Executing <Task(BashOperator): eventos_dim> on 2022-09-01 00:00:00+00:00
[2022-10-26 14:28:01,238] {standard_task_runner.py:52} INFO - Started process 287 to run task
[2022-10-26 14:28:01,244] {standard_task_runner.py:79} INFO - Running: ['***', 'tasks', 'run', 'dbt_dim', 'eventos_dim', 'scheduled__2022-09-01T00:00:00+00:00', '--job-id', '17', '--raw', '--subdir', 'DAGS_FOLDER/dbt_dim.py', '--cfg-path', '/tmp/tmpp4f5t1n7', '--error-file', '/tmp/tmpnhniycq6']
[2022-10-26 14:28:01,246] {standard_task_runner.py:80} INFO - Job 17: Subtask eventos_dim
[2022-10-26 14:28:01,321] {task_command.py:369} INFO - Running <TaskInstance: dbt_dim.eventos_dim scheduled__2022-09-01T00:00:00+00:00 [running]> on host d860ef10ab5f
[2022-10-26 14:28:01,424] {taskinstance.py:1571} INFO - Exporting the following env vars:
AIRFLOW_CTX_DAG_OWNER=***
AIRFLOW_CTX_DAG_ID=dbt_dim
AIRFLOW_CTX_TASK_ID=eventos_dim
AIRFLOW_CTX_EXECUTION_DATE=2022-09-01T00:00:00+00:00
AIRFLOW_CTX_TRY_NUMBER=1
AIRFLOW_CTX_DAG_RUN_ID=scheduled__2022-09-01T00:00:00+00:00
[2022-10-26 14:28:01,426] {subprocess.py:62} INFO - Tmp dir root location: 
 /tmp
[2022-10-26 14:28:01,427] {subprocess.py:74} INFO - Running command: ['bash', '-c', 'cd /opt/dbt/oly_dbt && dbt run --select +eventos_dim']
[2022-10-26 14:28:01,437] {subprocess.py:85} INFO - Output:
[2022-10-26 14:28:06,802] {subprocess.py:92} INFO - [0m14:28:06  Running with dbt=1.3.0
[2022-10-26 14:28:06,957] {subprocess.py:92} INFO - [0m14:28:06  Partial parse save file not found. Starting full parse.
[2022-10-26 14:28:09,068] {subprocess.py:92} INFO - [0m14:28:09  [[33mWARNING[0m]: Configuration paths exist in your dbt_project.yml file which do not apply to any resources.
[2022-10-26 14:28:09,068] {subprocess.py:92} INFO - There are 1 unused configuration paths:
[2022-10-26 14:28:09,069] {subprocess.py:92} INFO - - models.oly_dbt.example
[2022-10-26 14:28:09,069] {subprocess.py:92} INFO - 
[2022-10-26 14:28:09,112] {subprocess.py:92} INFO - [0m14:28:09  Found 2 models, 0 tests, 0 snapshots, 0 analyses, 289 macros, 0 operations, 0 seed files, 0 sources, 0 exposures, 0 metrics
[2022-10-26 14:28:09,117] {subprocess.py:92} INFO - [0m14:28:09
[2022-10-26 14:28:09,343] {subprocess.py:92} INFO - [0m14:28:09  Concurrency: 4 threads (target='dev')
[2022-10-26 14:28:09,344] {subprocess.py:92} INFO - [0m14:28:09
[2022-10-26 14:28:09,350] {subprocess.py:92} INFO - [0m14:28:09  1 of 1 START sql view model public.eventos_dim ................................. [RUN]
[2022-10-26 14:28:09,532] {subprocess.py:92} INFO - [0m14:28:09  1 of 1 OK created sql view model public.eventos_dim ............................ [[32mCREATE VIEW[0m in 0.18s]
[2022-10-26 14:28:09,560] {subprocess.py:92} INFO - [0m14:28:09
[2022-10-26 14:28:09,560] {subprocess.py:92} INFO - [0m14:28:09  Finished running 1 view model in 0 hours 0 minutes and 0.44 seconds (0.44s).
[2022-10-26 14:28:09,572] {subprocess.py:92} INFO - [0m14:28:09
[2022-10-26 14:28:09,573] {subprocess.py:92} INFO - [0m14:28:09  [32mCompleted successfully[0m
[2022-10-26 14:28:09,573] {subprocess.py:92} INFO - [0m14:28:09
[2022-10-26 14:28:09,574] {subprocess.py:92} INFO - [0m14:28:09  Done. PASS=1 WARN=0 ERROR=0 SKIP=0 TOTAL=1
[2022-10-26 14:28:10,695] {subprocess.py:96} INFO - Command exited with return code 0
[2022-10-26 14:28:10,752] {taskinstance.py:1400} INFO - Marking task as SUCCESS. dag_id=dbt_dim, task_id=eventos_dim, execution_date=20220901T000000, start_date=20221026T142801, end_date=20221026T142810
[2022-10-26 14:28:10,808] {local_task_job.py:156} INFO - Task exited with return code 0
[2022-10-26 14:28:10,840] {local_task_job.py:273} INFO - 0 downstream tasks scheduled from follow-on schedule check
[2022-10-26 14:48:15,609] {taskinstance.py:1159} INFO - Dependencies all met for <TaskInstance: dbt_dim.eventos_dim scheduled__2022-09-01T00:00:00+00:00 [queued]>
[2022-10-26 14:48:15,625] {taskinstance.py:1159} INFO - Dependencies all met for <TaskInstance: dbt_dim.eventos_dim scheduled__2022-09-01T00:00:00+00:00 [queued]>
[2022-10-26 14:48:15,625] {taskinstance.py:1356} INFO - 
--------------------------------------------------------------------------------
[2022-10-26 14:48:15,625] {taskinstance.py:1357} INFO - Starting attempt 1 of 2
[2022-10-26 14:48:15,625] {taskinstance.py:1358} INFO - 
--------------------------------------------------------------------------------
[2022-10-26 14:48:15,645] {taskinstance.py:1377} INFO - Executing <Task(BashOperator): eventos_dim> on 2022-09-01 00:00:00+00:00
[2022-10-26 14:48:15,650] {standard_task_runner.py:52} INFO - Started process 315 to run task
[2022-10-26 14:48:15,654] {standard_task_runner.py:79} INFO - Running: ['***', 'tasks', 'run', 'dbt_dim', 'eventos_dim', 'scheduled__2022-09-01T00:00:00+00:00', '--job-id', '18', '--raw', '--subdir', 'DAGS_FOLDER/dbt_dim.py', '--cfg-path', '/tmp/tmpin774s7_', '--error-file', '/tmp/tmp4klqmfs9']
[2022-10-26 14:48:15,656] {standard_task_runner.py:80} INFO - Job 18: Subtask eventos_dim
[2022-10-26 14:48:15,727] {task_command.py:369} INFO - Running <TaskInstance: dbt_dim.eventos_dim scheduled__2022-09-01T00:00:00+00:00 [running]> on host 4af2e895db31
[2022-10-26 14:48:15,851] {taskinstance.py:1571} INFO - Exporting the following env vars:
AIRFLOW_CTX_DAG_OWNER=***
AIRFLOW_CTX_DAG_ID=dbt_dim
AIRFLOW_CTX_TASK_ID=eventos_dim
AIRFLOW_CTX_EXECUTION_DATE=2022-09-01T00:00:00+00:00
AIRFLOW_CTX_TRY_NUMBER=1
AIRFLOW_CTX_DAG_RUN_ID=scheduled__2022-09-01T00:00:00+00:00
[2022-10-26 14:48:15,852] {subprocess.py:62} INFO - Tmp dir root location: 
 /tmp
[2022-10-26 14:48:15,854] {subprocess.py:74} INFO - Running command: ['bash', '-c', 'cd /opt/dbt/oly_dbt/models/dim_tables && dbt run --select +eventos_dim']
[2022-10-26 14:48:15,874] {subprocess.py:85} INFO - Output:
[2022-10-26 14:48:20,271] {subprocess.py:92} INFO - [0m14:48:20  Encountered an error while reading the project:
[2022-10-26 14:48:20,272] {subprocess.py:92} INFO - [0m14:48:20    ERROR: Runtime Error
[2022-10-26 14:48:20,273] {subprocess.py:92} INFO -   Could not find profile named 'oly_dbt'
[2022-10-26 14:48:20,290] {subprocess.py:92} INFO - [0m14:48:20  Encountered an error:
[2022-10-26 14:48:20,290] {subprocess.py:92} INFO - Runtime Error
[2022-10-26 14:48:20,291] {subprocess.py:92} INFO -   Could not run dbt
[2022-10-26 14:48:20,598] {subprocess.py:96} INFO - Command exited with return code 2
[2022-10-26 14:48:20,641] {taskinstance.py:1889} ERROR - Task failed with exception
Traceback (most recent call last):
  File "/home/airflow/.local/lib/python3.7/site-packages/airflow/operators/bash.py", line 195, in execute
    f'Bash command failed. The command returned a non-zero exit code {result.exit_code}.'
airflow.exceptions.AirflowException: Bash command failed. The command returned a non-zero exit code 2.
[2022-10-26 14:48:20,646] {taskinstance.py:1400} INFO - Marking task as UP_FOR_RETRY. dag_id=dbt_dim, task_id=eventos_dim, execution_date=20220901T000000, start_date=20221026T144815, end_date=20221026T144820
[2022-10-26 14:48:20,661] {standard_task_runner.py:97} ERROR - Failed to execute job 18 for task eventos_dim (Bash command failed. The command returned a non-zero exit code 2.; 315)
[2022-10-26 14:48:20,674] {local_task_job.py:156} INFO - Task exited with return code 1
[2022-10-26 14:48:20,747] {local_task_job.py:273} INFO - 0 downstream tasks scheduled from follow-on schedule check
